<?xml version='1.0'?>

<robot name="sg_bot" xmlns:xacro="http://www.ros.org/wiki/xacro">

  <xacro:include filename="$(find sg_bot)/urdf/sg_bot.gazebo"/>

  <link name="robot_footprint"></link>

  <joint name="robot_footprint_joint" type="fixed">
    <origin xyz="0 0 0" rpy="0 0 0" />
    <parent link="robot_footprint"/>
    <child link="chassis" />
  </joint>

  <material name="blue">
    <color rgba="0 0 0.8 1"/>
  </material>
  <material name="green">
    <color rgba="0 1 0 1"/>
  </material>
  <material name="black">
    <color rgba="0 0 0 1"/>
  </material>
  <material name="white">
    <color rgba="1 1 1 1"/>
  </material>
  
  <link name='chassis'>
    <pose>0 0 0.1 0 0 0</pose>

    <inertial>
      <mass value="12.0"/>
      <origin xyz="0.0 0 0" rpy=" 0 0 0"/>
      <inertia
          ixx="0.1" ixy="0" ixz="0"
          iyy="0.1" iyz="0"
          izz="0.1"
      />
    </inertial>

    <collision name='collision'>
      <origin xyz="0 0 0" rpy=" 0 0 0"/> 
      <geometry>
        <box size=".4 .2 .1"/>
      </geometry>
    </collision>

    <visual name='chassis_visual'>
      <origin xyz="0 0 0" rpy=" 0 0 0"/>
      <geometry>
        <box size=".4 .2 .1"/>
      </geometry>
      <material name="blue"/>
    </visual>
    
    <visual name='front_bump_visual'>
      <origin xyz="0.25 0 0" rpy=" 0 0 0"/>
      <geometry>
        <box size=".1 .1 .1"/>
      </geometry>
      <material name="blue"/>
    </visual>
   
    <collision name='front_bump_collision'>
      <origin xyz="0.25 0 0" rpy=" 0 0 0"/>
      <geometry>
        <box size=".1 .1 .1"/>
      </geometry>
    </collision>

    <collision name='back_caster_collision'>
      <origin xyz="-0.15 0 -0.05" rpy=" 0 0 0"/>
      <geometry>
        <sphere radius="0.0499"/>
      </geometry>
    </collision>

    <visual name='back_caster_visual'>
      <origin xyz="-0.15 0 -0.05" rpy=" 0 0 0"/>
      <geometry>
        <sphere radius="0.05"/>
      </geometry>
      <material name="black"/>
    </visual>
	
	<visual name='center_cylinder_visual'>
	  <origin xyz="0 0 0.2" rpy=" 0 0 0"/>
      <geometry>
         <cylinder length="0.3" radius="0.05"/>
      </geometry>
      <material name="green"/>
    </visual>
	
	<collision name='center_cylinder_collision'>
      <origin xyz="0 0 0.2" rpy=" 0 0 0"/>
      <geometry>
        <cylinder length="0.3" radius="0.05"/>
      </geometry>
    </collision>
    
    <visual name='left_back_cylinder_visual'>
	  <origin xyz="-0.19 0.09 0.2" rpy=" 0 0 0"/>
      <geometry>
         <cylinder length="0.3" radius="0.01"/>
      </geometry>
      <material name="green"/>
    </visual>
	
	<collision name='left_back_cylinder_collision'>
      <origin xyz="-0.19 0.09 0.2" rpy=" 0 0 0"/>
      <geometry>
        <cylinder length="0.3" radius="0.01"/>
      </geometry>
    </collision>
    
    <visual name='right_back_cylinder_visual'>
	  <origin xyz="-0.19 -0.09 0.2" rpy=" 0 0 0"/>
      <geometry>
         <cylinder length="0.3" radius="0.01"/>
      </geometry>
      <material name="green"/>
    </visual>
	
	<collision name='right_back_cylinder_collision'>
      <origin xyz="-0.19 -0.09 0.2" rpy=" 0 0 0"/>
      <geometry>
        <cylinder length="0.3" radius="0.01"/>
      </geometry>
    </collision>
    
    <visual name='back_left_top_box_visual'>
	  <origin xyz="-0.12 0.045 0.34" rpy=" 0 0 -0.6"/>
      <geometry>
         <box size=".17 .02 .02"/>
      </geometry>
      <material name="green"/>
    </visual>
	
	<collision name='back_left_top_box_collision'>
      <origin xyz="-0.12 0.045 0.34" rpy=" 0 0 -0.6"/>
      <geometry>
        <box size=".17 .02 .02"/>
      </geometry>
    </collision>
    
     <visual name='back_right_top_box_visual'>
	  <origin xyz="-0.12 -0.045 0.34" rpy=" 0 0 0.6"/>
      <geometry>
         <box size=".17 .02 .02"/>
      </geometry>
      <material name="green"/>
    </visual>
	
	<collision name='back_right_top_box_collision'>
      <origin xyz="-0.12 -0.045 0.34" rpy=" 0 0 0.6"/>
      <geometry>
        <box size=".17 .02 .02"/>
      </geometry>
    </collision>
    
    <visual name='front_left_cylinder_visual'>
	  <origin xyz="0.19 0.09 0.2" rpy=" 0 0 0"/>
      <geometry>
         <cylinder length="0.3" radius="0.01"/>
      </geometry>
      <material name="green"/>
    </visual>
	
	<collision name='front_left_cylinder_collision'>
      <origin xyz="0.19 0.09 0.2" rpy=" 0 0 0"/>
      <geometry>
        <cylinder length="0.3" radius="0.01"/>
      </geometry>
    </collision>
    
    <visual name='front_right_cylinder_visual'>
	  <origin xyz="0.19 -0.09 0.2" rpy=" 0 0 0"/>
      <geometry>
         <cylinder length="0.3" radius="0.01"/>
      </geometry>
      <material name="green"/>
    </visual>
	
	<collision name='front_right_cylinder_collision'>
      <origin xyz="0.19 -0.09 0.2" rpy=" 0 0 0"/>
      <geometry>
        <cylinder length="0.3" radius="0.01"/>
      </geometry>
    </collision>
    
    <visual name='front_top_box_visual'>
	  <origin xyz="0.19 0.0 0.34" rpy=" 0 0 -1.57075"/>
      <geometry>
         <box size=".18 .02 .02"/>
      </geometry>
      <material name="green"/>
    </visual>
	
	<collision name='front_top_box_collision'>
      <origin xyz="0.19 0.0 0.34" rpy=" 0 0 -1.57075"/>
      <geometry>
        <box size=".18 .02 .02"/>
      </geometry>
    </collision>
    
     <visual name='front_center_top_box_visual'>
	  <origin xyz="0.12 0.0 0.34" rpy=" 0 0 0"/>
      <geometry>
         <box size=".14 .02 .02"/>
      </geometry>
      <material name="green"/>
    </visual>
	
	<collision name='front_center_top_box_collision'>
      <origin xyz="0.12 0.0 0.34" rpy=" 0 0 0.0"/>
      <geometry>
        <box size=".14 .02 .02"/>
      </geometry>
    </collision>
    
  </link>

  <xacro:macro name="wheel" params="prefix reflect">
    <link name="${prefix}_wheel">
      <visual>
        <origin xyz="0 0 0" rpy="0 1.57075 1.57075"/>
        <geometry>
          <cylinder length="0.05" radius="0.1"/>
        </geometry>
        <material name="black"/>
      </visual>
  
      <collision>
        <origin xyz="0 0 0" rpy="0 1.57075 1.57075"/>
        <geometry>
          <cylinder length="0.05" radius="0.1"/>
        </geometry>
      </collision>
    
      <inertial>
        <mass value="2"/>
        <inertia
          ixx="0.1" ixy="0" ixz="0"
          iyy="0.1" iyz="0"
          izz="0.1"/>
      </inertial>
    </link>
    
    <joint type="continuous" name="${prefix}_wheel_hinge">
      <origin xyz="0.125 ${reflect*0.15} 0" rpy="0 0 0"/>
      <child link="${prefix}_wheel"/>
      <parent link="chassis"/>
      <axis xyz="0 1 0" rpy="0 0 0"/>
      <limit effort="10000" velocity="1000"/>
      <dynamics damping="1.0" friction="1.0"/>
    </joint>
  </xacro:macro>

  <xacro:wheel prefix="left" reflect="1" />
  <xacro:wheel prefix="right" reflect="-1" />

  <link name="camera">
    <visual>
      <origin xyz="0 0 0" rpy="0 0 0"/>
      <geometry>
        <box size="0.05 0.05 0.05"/>
      </geometry>
    </visual>

    <collision>
      <geometry>
        <box size="0.05 0.05 0.05" />
      </geometry>
    </collision>
    
    <inertial>
      <mass value="0.1"/>
      <inertia
        ixx="1e-6" ixy="0" ixz="0"
        iyy="1e-6" iyz="0"
        izz="1e-6" />
    </inertial>
  </link>

  <joint type="fixed" name="camera_joint">
    <origin xyz="0.19 0 0.35" rpy="0 0 0"/>
    <child link="camera"/>
    <parent link="chassis"/>
  </joint>

  <link name="hokuyo">
    <visual>
      <origin xyz="0 0 0" rpy="0 0 0"/>
      <geometry>
        <mesh filename="package://sg_bot/meshes/hokuyo.dae"/>
      </geometry>
    </visual>

    <collision>
      <geometry>
        <box size="0.1 0.1 0.1" />
      </geometry>
    </collision>
    
    <inertial>
      <mass value="0.1"/>
      <inertia
        ixx="1e-6" ixy="0" ixz="0"
        iyy="1e-6" iyz="0"
        izz="1e-6" />
    </inertial>
  </link>

  <joint type="fixed" name="hokuyo_joint">
    <origin xyz="0.25 0 0.1" rpy="0 0 0"/>
    <child link="hokuyo"/>
    <parent link="chassis"/>
  </joint>

</robot>